[2022-12-21T21:51:21.641+0000] {taskinstance.py:1087} INFO - Dependencies all met for <TaskInstance: data_ingestion_aws_dag.unzip_pgn_task manual__2022-12-21T21:51:12.376731+00:00 [queued]>
[2022-12-21T21:51:21.662+0000] {taskinstance.py:1087} INFO - Dependencies all met for <TaskInstance: data_ingestion_aws_dag.unzip_pgn_task manual__2022-12-21T21:51:12.376731+00:00 [queued]>
[2022-12-21T21:51:21.662+0000] {taskinstance.py:1283} INFO - 
--------------------------------------------------------------------------------
[2022-12-21T21:51:21.662+0000] {taskinstance.py:1284} INFO - Starting attempt 1 of 2
[2022-12-21T21:51:21.663+0000] {taskinstance.py:1285} INFO - 
--------------------------------------------------------------------------------
[2022-12-21T21:51:21.701+0000] {taskinstance.py:1304} INFO - Executing <Task(PythonOperator): unzip_pgn_task> on 2022-12-21 21:51:12.376731+00:00
[2022-12-21T21:51:21.712+0000] {standard_task_runner.py:55} INFO - Started process 553 to run task
[2022-12-21T21:51:21.717+0000] {standard_task_runner.py:82} INFO - Running: ['***', 'tasks', 'run', 'data_ingestion_aws_dag', 'unzip_pgn_task', 'manual__2022-12-21T21:51:12.376731+00:00', '--job-id', '20', '--raw', '--subdir', 'DAGS_FOLDER/data_ingestion_aws_dag.py', '--cfg-path', '/tmp/tmp7y0xibbh']
[2022-12-21T21:51:21.718+0000] {standard_task_runner.py:83} INFO - Job 20: Subtask unzip_pgn_task
[2022-12-21T21:51:21.864+0000] {task_command.py:389} INFO - Running <TaskInstance: data_ingestion_aws_dag.unzip_pgn_task manual__2022-12-21T21:51:12.376731+00:00 [running]> on host dd56c2ebcf51
[2022-12-21T21:51:22.064+0000] {taskinstance.py:1513} INFO - Exporting the following env vars:
AIRFLOW_CTX_DAG_OWNER=***
AIRFLOW_CTX_DAG_ID=data_ingestion_aws_dag
AIRFLOW_CTX_TASK_ID=unzip_pgn_task
AIRFLOW_CTX_EXECUTION_DATE=2022-12-21T21:51:12.376731+00:00
AIRFLOW_CTX_TRY_NUMBER=1
AIRFLOW_CTX_DAG_RUN_ID=manual__2022-12-21T21:51:12.376731+00:00
[2022-12-21T21:51:22.133+0000] {taskinstance.py:1772} ERROR - Task failed with exception
Traceback (most recent call last):
  File "/home/airflow/.local/lib/python3.7/site-packages/airflow/operators/python.py", line 175, in execute
    return_value = self.execute_callable()
  File "/home/airflow/.local/lib/python3.7/site-packages/airflow/operators/python.py", line 192, in execute_callable
    return self.python_callable(*self.op_args, **self.op_kwargs)
  File "/opt/airflow/dags/data_ingestion_aws_dag.py", line 21, in unzip_pgn
    with open(input_file, 'rb') as compressed:
FileNotFoundError: [Errno 2] No such file or directory: '/opt/***/lichess_db_standard_rated_2013-01.pgn.zst'
[2022-12-21T21:51:22.151+0000] {taskinstance.py:1327} INFO - Marking task as UP_FOR_RETRY. dag_id=data_ingestion_aws_dag, task_id=unzip_pgn_task, execution_date=20221221T215112, start_date=20221221T215121, end_date=20221221T215122
[2022-12-21T21:51:22.193+0000] {standard_task_runner.py:105} ERROR - Failed to execute job 20 for task unzip_pgn_task ([Errno 2] No such file or directory: '/opt/***/lichess_db_standard_rated_2013-01.pgn.zst'; 553)
[2022-12-21T21:51:22.216+0000] {local_task_job.py:159} INFO - Task exited with return code 1
[2022-12-21T21:51:22.270+0000] {taskinstance.py:2582} INFO - 0 downstream tasks scheduled from follow-on schedule check
