[2022-12-21T22:48:36.405+0000] {taskinstance.py:1087} INFO - Dependencies all met for <TaskInstance: data_ingestion_aws_dag.ingest_pgn_task manual__2022-12-21T22:42:48.871967+00:00 [queued]>
[2022-12-21T22:48:36.423+0000] {taskinstance.py:1087} INFO - Dependencies all met for <TaskInstance: data_ingestion_aws_dag.ingest_pgn_task manual__2022-12-21T22:42:48.871967+00:00 [queued]>
[2022-12-21T22:48:36.424+0000] {taskinstance.py:1283} INFO - 
--------------------------------------------------------------------------------
[2022-12-21T22:48:36.424+0000] {taskinstance.py:1284} INFO - Starting attempt 2 of 2
[2022-12-21T22:48:36.424+0000] {taskinstance.py:1285} INFO - 
--------------------------------------------------------------------------------
[2022-12-21T22:48:36.468+0000] {taskinstance.py:1304} INFO - Executing <Task(PythonOperator): ingest_pgn_task> on 2022-12-21 22:42:48.871967+00:00
[2022-12-21T22:48:36.475+0000] {standard_task_runner.py:55} INFO - Started process 71 to run task
[2022-12-21T22:48:36.479+0000] {standard_task_runner.py:82} INFO - Running: ['***', 'tasks', 'run', 'data_ingestion_aws_dag', 'ingest_pgn_task', 'manual__2022-12-21T22:42:48.871967+00:00', '--job-id', '31', '--raw', '--subdir', 'DAGS_FOLDER/data_ingestion_aws_dag.py', '--cfg-path', '/tmp/tmpicngzrri']
[2022-12-21T22:48:36.480+0000] {standard_task_runner.py:83} INFO - Job 31: Subtask ingest_pgn_task
[2022-12-21T22:48:36.600+0000] {task_command.py:389} INFO - Running <TaskInstance: data_ingestion_aws_dag.ingest_pgn_task manual__2022-12-21T22:42:48.871967+00:00 [running]> on host 71d54d8177f1
[2022-12-21T22:48:36.763+0000] {taskinstance.py:1513} INFO - Exporting the following env vars:
AIRFLOW_CTX_DAG_OWNER=***
AIRFLOW_CTX_DAG_ID=data_ingestion_aws_dag
AIRFLOW_CTX_TASK_ID=ingest_pgn_task
AIRFLOW_CTX_EXECUTION_DATE=2022-12-21T22:42:48.871967+00:00
AIRFLOW_CTX_TRY_NUMBER=2
AIRFLOW_CTX_DAG_RUN_ID=manual__2022-12-21T22:42:48.871967+00:00
[2022-12-21T22:48:36.869+0000] {taskinstance.py:1772} ERROR - Task failed with exception
Traceback (most recent call last):
  File "/home/airflow/.local/lib/python3.7/site-packages/airflow/operators/python.py", line 175, in execute
    return_value = self.execute_callable()
  File "/home/airflow/.local/lib/python3.7/site-packages/airflow/operators/python.py", line 192, in execute_callable
    return self.python_callable(*self.op_args, **self.op_kwargs)
  File "/opt/airflow/dags/data_ingestion_aws_dag.py", line 35, in ingest_pgn
    import chess
ModuleNotFoundError: No module named 'chess'
[2022-12-21T22:48:36.897+0000] {taskinstance.py:1327} INFO - Marking task as FAILED. dag_id=data_ingestion_aws_dag, task_id=ingest_pgn_task, execution_date=20221221T224248, start_date=20221221T224836, end_date=20221221T224836
[2022-12-21T22:48:36.947+0000] {standard_task_runner.py:105} ERROR - Failed to execute job 31 for task ingest_pgn_task (No module named 'chess'; 71)
[2022-12-21T22:48:36.972+0000] {local_task_job.py:159} INFO - Task exited with return code 1
[2022-12-21T22:48:37.005+0000] {taskinstance.py:2582} INFO - 0 downstream tasks scheduled from follow-on schedule check
